Workbook

Sheet #104 (2025-10-17)
A1: Good Life Toastmasters Club 美好人生英文俱樂部
A2: 地址：臺北市中山區復興北路150號9樓-小樹屋902房 (近捷運南京復興站8號出口步行3分鐘內)
A3: Address：Room 902, 9F., No. 150, Fuxing N. Rd., Zhongshan Dist., Taipei City (Near Nanjing Fuxing MRT Station Ext.8)
A4: Time: Every 1st & 3rd Friday Evening 7:15~9:15PM Charter in March.1st,2021
A5: Admission Fee: For members and guests $150 (Including snacks,drinks)
A7: Club Mission
A8: We provide a supportive and positive learning experience in which members are empowered to develop communication and leadership skills, resulting in greater self-confidence and personal growth.
A10: Meeting:#104 Date: Friday, Oct 17, 2025
A11: =CONCATENATE("Theme: ", parameters!E18, CHAR(10),"Question: ",parameters!F18) -> Theme: The Power of Words Question: Has someone’s words ever changed your life?
A12: Time | D12: Content | J12: Conductor | L12: Meeting Role
A13: 0.77083333 | B13: 0.78472222 | C13: 0.013888889 | D13: Preperation | J13: All Officers
A14: =B13 -> 0.78472222 | B14: =A14+C14 -> 0.80208333 | C14: 0.017361111 | D14: Reception | J14: All Officers
A15: =B14 -> 0.80208333 | B15: =A15+C15 -> 0.80277778 | C15: 0.00069444444 | D15: Call Meeting to order SAA | J15: Dennis Chen
A16: =B15 -> 0.80277778 | B16: =A16+C16 -> 0.80625 | C16: 0.0034722222 | D16: Opening Remarks & Guests Introduction | J16: President | K16: =Roles!D2 -> Dennis Chen, IP3
A17: =B16 -> 0.80625 | B17: 0.8125 | C17: 0.0020833333 | D17: Toastmaster of the Evening Introduction | J17: Member | K17: =Roles!D3 -> Dennis Chen, IP3 | L17: TME
C18: 0.0013888889 | D18: Timing Rules | J18: =Roles!D4 -> Regina Cheng, DTM | L18: Timer
C19: 0.0013888889 | D19: Ah Counter Rules | J19: =Roles!D5 -> Michael James | L19: Ah Counter
C20: 0.0013888889 | D20: Vote Counter Rules | J20: =Roles!D6 -> Regina Cheng, DTM | L20: Vote Counter
A21: 0.8125 | B21: =A21+C21 -> 0.81944444 | C21: 0.0069444444 | D21: Variety Session | J21: =Roles!D7 -> Maxim Niederau | L21: Session Master
A22: =B21 -> 0.81944444 | B22: =A22+C22 -> 0.82013889 | C22: 0.00069444444 | D22: Prepared Speech Session | J22: =Roles!D3 -> Dennis Chen, IP3 | L22: TME
A23: =B22 -> 0.82013889 | B23: =B22+parameters!B2-parameters!C2 -> 0.82430556 | C23: =parameters!D2 -> 5-7m | D23: =parameters!H2 -> L5P2 | E23: =CONCATENATE("Project: ", parameters!E2) -> Project: High Performance Leadership | J23: =Roles!D8 -> Javier Bernabeu, MS4 | L23: Speaker
D24: =CONCATENATE("Title: ", parameters!F2) -> Title: Moving Mountains From Inside Us
A25: =B23 -> 0.82430556 | B25: =B23+parameters!B3+parameters!C3 -> 0.82916667 | C25: =parameters!D3 -> 4-6m | D25: =parameters!H3 -> L1P1 | E25: =CONCATENATE("Project: ", parameters!E3) -> Project: Ice Breaker | J25: =Roles!D9 -> Tanya Chen(Sandwich) | L25: Speaker
D26: =CONCATENATE("Title: ", parameters!F3) -> Title: Voyage of Discovery
A27: =B25 -> 0.82916667 | B27: =B25+parameters!B4+parameters!C4 -> 0.83472222 | C27: =parameters!D4 -> 5-7m | D27: =parameters!H4 | E27: =CONCATENATE("Project: ", parameters!E4) -> Project: | J27: =Roles!D10 | L27: Speaker
D28: =CONCATENATE("Title: ", parameters!F4) -> Title:
A29: =B27 -> 0.83472222 | B29: =A29+C29 -> 0.83611111 | C29: 0.0013888889 | D29: 1st Timer & Ah Counter Report | J29: =CONCATENATE(Roles!$D$4," / ",Roles!$D$5) -> Regina Cheng, DTM / Michael James | L29: Timer/Ah Counter
A30: =B29 -> 0.83611111 | B30: =A30+C30 -> 0.84305556 | C30: 0.0069444444 | D30: Intermission & Group Photo | J30: =Roles!D12 -> Eloise Hsu, EH1 | L30: Photographer
A31: =B30 -> 0.84305556 | B31: =A31+C31 -> 0.85347222 | C31: 0.010416667 | D31: Table Topics Session | J31: =Roles!D13 -> Tappy Hsieh, PM2 | L31: Session Master
A32: =B31 -> 0.85347222 | B32: =A32+C32 -> 0.85555556 | C32: 0.0020833333 | D32: Evaluation Session | J32: =Roles!D14 -> Alex Huang, PM3 | L32: GE
A33: =B32 -> 0.85555556 | B33: =B32+parameters!B6+parameters!C6 -> 0.85833333 | C33: =parameters!D6 -> 2-3m | D33: =CONCATENATE("Individual Evaluator #1 for ",Roles!D8) -> Individual Evaluator #1 for Javier Bernabeu, MS4 | J33: =Roles!D15 -> Carol Chang, PM3 | L33: IE
A34: =B33 -> 0.85833333 | B34: =B33+parameters!B7+parameters!C7 -> 0.86111111 | C34: =parameters!D7 -> 2-3m | D34: =CONCATENATE("Individual Evaluator #2 for ",Roles!D9) -> Individual Evaluator #2 for Tanya Chen(Sandwich) | J34: =Roles!D16 -> Pearl Huang, LD4 | L34: IE
A35: =B34 -> 0.86111111 | B35: =B34+parameters!B7+parameters!C7 -> 0.86388889 | C35: =parameters!D8 -> 2-3m | D35: =CONCATENATE("Individual Evaluator #3 for ",Roles!D10) -> Individual Evaluator #3 for | J35: =Roles!D17 | L35: IE
A36: =B34 -> 0.86111111 | B36: =A36+C36 -> 0.8625 | C36: 0.0013888889 | D36: 2nd Timer & Ah Counter Report | J36: =CONCATENATE(Roles!$D$4," / ",Roles!$D$5) -> Regina Cheng, DTM / Michael James | L36: Timer/Ah Counter
A37: =B36 -> 0.8625 | B37: =A37+parameters!B11+parameters!C11 -> 0.86736111 | C37: =parameters!D11 -> 4-6m | D37: Language Evaluation Session | J37: =Roles!D20 -> Eloise Hsu, EH1 | L37: LE
A38: =B37 -> 0.86736111 | B38: =B37+parameters!B12+parameters!C12 -> 0.87222222 | C38: =parameters!D12 -> 4-6m | D38: General Evaluation Session | J38: =Roles!B14 -> Alex Huang | L38: GE
A39: =B38 -> 0.87222222 | B39: =A39+C39 -> 0.87291667 | C39: 0.00069444444 | D39: Voting Time | J39: =Roles!D2 -> Dennis Chen, IP3 | L39: TME
A40: =B39 -> 0.87291667 | B40: =A40+C40 -> 0.87638889 | C40: 0.0034722222 | D40: Awarding & Appreciation | J40: =Roles!D2 -> Dennis Chen, IP3
A41: =B40 -> 0.87638889 | B41: =A41+C41 -> 0.87986111 | C41: 0.0034722222 | D41: Guest Sharing & Announcement | J41: President | K41: =Roles!D2 -> Dennis Chen, IP3
A42: =B41 -> 0.87986111 | B42: =A42+C42 -> 0.88055556 | C42: 0.00069444444 | D42: Meeting Adjourn
...

Sheet parameters
A1: Item | B1: Duration | C1: Buffer | D1: Display Time | E1: Project | F1: Title | G1: Pathway | I1: Pathway(Abbr.)
A2: speaker1 | B2: 0.0048611111 | C2: 0.00069444444 | D2: =VLOOKUP(B2,$A$17:$B$24,2) -> 5-7m | E2: High Performance Leadership | F2: Moving Mountains From Inside Us | G2: Motivational Strategies | H2: L5P2 | I2: MS
A3: speaker2 | B3: 0.0041666667 | C3: 0.00069444444 | D3: =VLOOKUP(B3,$A$18:$B$24,2) -> 4-6m | E3: Ice Breaker | F3: Voyage of Discovery | G3: Presentation Mastery | H3: L1P1 | I3: PM
A4: speaker3 | B4: 0.0048611111 | C4: 0.00069444444 | D4: =VLOOKUP(B4,$A$18:$B$24,2) -> 5-7m | I4: =IF(ISNA(VLOOKUP(G4,Purpose!$A$2:$B$128,2, false)), "", VLOOKUP(G4,Purpose!$A$2:$B$128,2, false))
A5: speaker4 | B5: 0.0048611111 | C5: 0.00069444444 | D5: =VLOOKUP(B5,$A$18:$B$24,2) -> 5-7m | I5: =IF(ISNA(VLOOKUP(G5,Purpose!$A$2:$B$128,2, false)), "", VLOOKUP(G5,Purpose!$A$2:$B$128,2, false))
A6: IE1 | B6: 0.0020833333 | C6: 0.00069444444 | D6: =VLOOKUP(B6,$C$18:$D$24,2) -> 2-3m | I6: =IF(ISNA(VLOOKUP(G6,Purpose!$A$2:$B$128,2, false)), "", VLOOKUP(G6,Purpose!$A$2:$B$128,2, false))
A7: IE2 | B7: 0.0020833333 | C7: 0.00069444444 | D7: =VLOOKUP(B7,$C$18:$D$24,2) -> 2-3m | I7: =IF(ISNA(VLOOKUP(G6,Purpose!$A$2:$B$128,2, false)), "", VLOOKUP(G6,Purpose!$A$2:$B$128,2, false))
A8: IE3 | B8: 0.0020833333 | C8: 0.00069444444 | D8: =VLOOKUP(B8,$C$18:$D$24,2) -> 2-3m | I8: =IF(ISNA(VLOOKUP(G7,Purpose!$A$2:$B$128,2, false)), "", VLOOKUP(G7,Purpose!$A$2:$B$128,2, false))
A9: IE4 | B9: 0.0020833333 | C9: 0.00069444444 | D9: =VLOOKUP(B9,$C$18:$D$24,2) -> 2-3m | I9: =IF(ISNA(VLOOKUP(G8,Purpose!$A$2:$B$128,2, false)), "", VLOOKUP(G8,Purpose!$A$2:$B$128,2, false))
A10: EE | B10: 0.0020833333 | C10: 0.00069444444 | D10: =VLOOKUP(B10,$C$18:$D$24,2) -> 2-3m
A11: LE | B11: 0.0041666667 | C11: 0.00069444444 | D11: =VLOOKUP(B11,$A$18:$B$24,2) -> 4-6m | I11: =IF(ISNA(VLOOKUP(G9,Purpose!$A$2:$B$128,2, false)), "", VLOOKUP(G9,Purpose!$A$2:$B$128,2, false))
A12: GE | B12: 0.0041666667 | C12: 0.00069444444 | D12: =VLOOKUP(B12,$A$18:$B$24,2) -> 4-6m | I12: =IF(ISNA(VLOOKUP(G11,Purpose!$A$2:$B$128,2, false)), "", VLOOKUP(G11,Purpose!$A$2:$B$128,2, false))
A16: Max. Speech Time | B16: Display Time | C16: Max. Time IE | D16: Display Time | E16: Theme | F16: Question
A17: 0.0034722222 | B17: 3-4m
A18: 0.0041666667 | B18: 4-6m | C18: 0.0020833333 | D18: 2-3m | E18: The Power of Words | F18: Has someone’s words ever changed your life?
A19: 0.0048611111 | B19: 5-7m
A20: 0.0055555556 | B20: 6-8m
A21: 0.00625 | B21: 7-9m
A22: 0.0069444444 | B22: 8-10m
A23: 0.0076388889 | B23: 9-11m
A24: 0.0083333333 | B24: 10-12m
A25: 0.013194444 | B25: 22m

Sheet Roles
A1: Role | B1: Name | C1: Pathway | D1: Display Name
A2: President | B2: Dennis Chen | C2: =IF(ISNA(VLOOKUP(B2,Pathways!$A$2:$B$46,2, false)), "", VLOOKUP(B2,Pathways!$A$2:$B$46,2, false)) -> IP3 | D2: =IF(C2="",B2, CONCATENATE(B2,", " & C2)) -> Dennis Chen, IP3
A3: TME | B3: Dennis Chen | C3: =IF(ISNA(VLOOKUP(B3,Pathways!$A$2:$B$46,2, false)), "", VLOOKUP(B3,Pathways!$A$2:$B$46,2, false)) -> IP3 | D3: =IF(C3="",B3, CONCATENATE(B3,", " & C3)) -> Dennis Chen, IP3
A4: Timer | B4: Regina Cheng | C4: =IF(ISNA(VLOOKUP(B4,Pathways!$A$2:$B$46,2, false)), "", VLOOKUP(B4,Pathways!$A$2:$B$46,2, false)) -> DTM | D4: =IF(C4="",B4, CONCATENATE(B4,", " & C4)) -> Regina Cheng, DTM
A5: Ah Counter | B5: Michael James | C5: =IF(ISNA(VLOOKUP(B5,Pathways!$A$2:$B$46,2, false)), "", VLOOKUP(B5,Pathways!$A$2:$B$46,2, false)) | D5: =IF(C5="",B5, CONCATENATE(B5,", " & C5)) -> Michael James
A6: Vote Counter | B6: Regina Cheng | C6: =IF(ISNA(VLOOKUP(B6,Pathways!$A$2:$B$46,2, false)), "", VLOOKUP(B6,Pathways!$A$2:$B$46,2, false)) -> DTM | D6: =IF(C6="",B6, CONCATENATE(B6,", " & C6)) -> Regina Cheng, DTM
A7: Variety Session Master | B7: Maxim Niederau | C7: =IF(ISNA(VLOOKUP(B7,Pathways!$A$2:$B$46,2, false)), "", VLOOKUP(B7,Pathways!$A$2:$B$46,2, false)) | D7: =IF(C7="",B7, CONCATENATE(B7,", " & C7)) -> Maxim Niederau
A8: Speaker1 | B8: Javier Bernabeu, MS4 | C8: =IF(ISNA(VLOOKUP(B8,Pathways!$A$2:$B$46,2, false)), "", VLOOKUP(B8,Pathways!$A$2:$B$46,2, false)) | D8: =IF(C8="",B8, CONCATENATE(B8,", " & C8)) -> Javier Bernabeu, MS4
A9: Speaker2 | B9: Tanya Chen(Sandwich) | C9: =IF(ISNA(VLOOKUP(B9,Pathways!$A$2:$B$46,2, false)), "", VLOOKUP(B9,Pathways!$A$2:$B$46,2, false)) | D9: =IF(C9="",B9, CONCATENATE(B9,", " & C9)) -> Tanya Chen(Sandwich)
A10: Speaker3 | C10: =IF(ISNA(VLOOKUP(B10,Pathways!$A$2:$B$46,2, false)), "", VLOOKUP(B10,Pathways!$A$2:$B$46,2, false)) | D10: =IF(C10="",B10, CONCATENATE(B10,", " & C10))
A11: Speaker4 | C11: =IF(ISNA(VLOOKUP(B11,Pathways!$A$2:$B$46,2, false)), "", VLOOKUP(B11,Pathways!$A$2:$B$46,2, false)) | D11: =IF(C11="",B11, CONCATENATE(B11,", " & C11))
A12: Photographer | B12: Eloise Hsu | C12: =IF(ISNA(VLOOKUP(B12,Pathways!$A$2:$B$46,2, false)), "", VLOOKUP(B12,Pathways!$A$2:$B$46,2, false)) -> EH1 | D12: =IF(C12="",B12, CONCATENATE(B12,", " & C12)) -> Eloise Hsu, EH1
A13: Table Topic Session Master | B13: Tappy Hsieh | C13: =IF(ISNA(VLOOKUP(B13,Pathways!$A$2:$B$46,2, false)), "", VLOOKUP(B13,Pathways!$A$2:$B$46,2, false)) -> PM2 | D13: =IF(C13="",B13, CONCATENATE(B13,", " & C13)) -> Tappy Hsieh, PM2
A14: GE | B14: Alex Huang | C14: PM3 | D14: =IF(C14="",B14, CONCATENATE(B14,", " & C14)) -> Alex Huang, PM3
A15: IE1 | B15: Carol Chang | C15: =IF(ISNA(VLOOKUP(B15,Pathways!$A$2:$B$46,2, false)), "", VLOOKUP(B15,Pathways!$A$2:$B$46,2, false)) -> PM3 | D15: =IF(C15="",B15, CONCATENATE(B15,", " & C15)) -> Carol Chang, PM3
A16: IE2 | B16: Pearl Huang | C16: =IF(ISNA(VLOOKUP(B16,Pathways!$A$2:$B$46,2, false)), "", VLOOKUP(B16,Pathways!$A$2:$B$46,2, false)) -> LD4 | D16: =IF(C16="",B16, CONCATENATE(B16,", " & C16)) -> Pearl Huang, LD4
A17: IE3 | C17: =IF(ISNA(VLOOKUP(B17,Pathways!$A$2:$B$46,2, false)), "", VLOOKUP(B17,Pathways!$A$2:$B$46,2, false)) | D17: =IF(C17="",B17, CONCATENATE(B17,", " & C17))
A18: IE4 | C18: =IF(ISNA(VLOOKUP(B18,Pathways!$A$2:$B$46,2, false)), "", VLOOKUP(B18,Pathways!$A$2:$B$46,2, false)) | D18: =IF(C18="",B18, CONCATENATE(B18,", " & C18))
A19: EE | C19: =IF(ISNA(VLOOKUP(B19,Pathways!$A$2:$B$46,2, false)), "", VLOOKUP(B19,Pathways!$A$2:$B$46,2, false)) | D19: =IF(C19="",B19, CONCATENATE(B19,", " & C19))
A20: LE | B20: Eloise Hsu | C20: =IF(ISNA(VLOOKUP(B20,Pathways!$A$2:$B$46,2, false)), "", VLOOKUP(B20,Pathways!$A$2:$B$46,2, false)) -> EH1 | D20: =IF(C20="",B20, CONCATENATE(B20,", " & C20)) -> Eloise Hsu, EH1
A23: absent | B23: Hana Bruce
B25: Bruce Fan
B26: Anabela Liang | C26: Michael Yu(Challengers)
B27: Nancy Nguyen
B28: Quentin Yao
B29: Yaya Liao
B30: Alex Huang
B31: Eric Tang
B32: Tappy Hsieh
B33: Eloise Hsu
B34: Dennis Chen
B35: Pearl Huang
B36: Augustine Chang (EYT)
B37: Yaya Liao
B38: Eric Tang
... B47: Michael James

Sheet Purpose
A1: Pathways | B1: Abbreviation | C1: Level | D1: Project | E1: Purpose Statement
A2: Dynamic Leadership | B2: DL | C2: L1P1 | D2: Ice Breaker | E2: ■ The purpose of this project is for the member to introduce themselves to the club and learn the basic structure of a public speech.
C3: L1P2 | D3: Writing a Speech with Purpose | E3: ■ The purpose of this project is to learn or review basic methods for writing a speech with a defined purpose and to present a well-organized speech on any topic.
C4: L1P3 | D4: Introduction to Vocal Variety and Body Language | E4: ■ The purpose of this project is for the member to practice using vocal variety or body language to enhance a speech.
C5: L1P4 | D5: Evaluation and Feedback | E5: ■ The purpose of this project is to practice applying feedback and serve as a speech evaluator during a club meeting. ■ The purpose of this speech is for the member to present a speech and receive feedback from the evaluator.
C6: L2P1 | D6: Understanding Your Leadership Style | E6: ■ The purpose of this project is for the member to identify his or her primary leadership style or styles. ■ The purpose of this speech is for the member to share some aspect of his or her primary leadership style or discuss leadership styles in general.
C7: L2P2 | D7: Understanding Your Communication Style | E7: ■ The purpose of this project is for the member to learn about different communication styles and identify his or her primary style. ■ The purpose of this speech is for the member to share the impact of his or her style on others.
C8: L2P3 | D8: Introduction to Toastmasters Mentoring | E8: ■ The purpose of this project is for the member to clearly define how Toastmasters envisions mentoring. ■ The purpose of this speech is for the member to share some aspect of a previous experience as a protégé.
C9: L3P1 | D9: Negotiate the Best Outcome | E9: ■ The purpose of this project is for the member to learn about different types of negotiation and the strategies that can be used when negotiating. ■ The purpose of this speech is for the member to share some aspect of a past or future negotiation in his or her life.
C10: L4P1 | D10: Manage Change | E10: ■ The purpose of this project is for the member to practice developing a change management plan. ■ The purpose of this speech is for the member to share some aspect of a change management plan.
C11: L5P1 | D11: Lead in Any Situation | E11: ■ The purpose of this project is for the member to apply the skills needed to successfully lead in a volunteer or other organization. ■ The purpose of this speech is for the member to share some aspect of his or her experience as a leader and/or the impact of the 360° evaluation.
C12: L5P2 | D12: Reflect on Your Path | E12: ■ The purpose of this project is for the member to reflect on his or her growth during the completion of an entire path. ■ The purpose of the speech is for the member to share some aspect of his or her growth during the completion of a path.
A13: Effective Coaching | B13: EC | C13: L1P1 | D13: Ice Breaker | E13: ■ The purpose of this project is for the member to introduce themselves to the club and learn the basic structure of a public speech.
C14: L1P2 | D14: Writing a Speech with Purpose | E14: ■ The purpose of this project is to learn or review basic methods for writing a speech with a defined purpose and to present a well-organized speech on any topic.
C15: L1P3 | D15: Introduction to Vocal Variety and Body Language | E15: ■ The purpose of this project is for the member to practice using vocal variety or body language to enhance a speech.
C16: L1P4 | D16: Evaluation and Feedback | E16: ■ The purpose of this project is to practice applying feedback and serve as a speech evaluator during a club meeting. ■ The purpose of this speech is for the member to present a speech and receive feedback from the evaluator.
C17: L2P1 | D17: Understanding Your Leadership Style | E17: ■ The purpose of this project is for the member to identify his or her primary leadership style or styles. ■ The purpose of this speech is for the member to share some aspect of his or her primary leadership style or discuss leadership styles in general.
C18: L2P2 | D18: Understanding Your Communication Style | E18: ■ The purpose of this project is for the member to learn about different communication styles and identify his or her primary style. ■ The purpose of this speech is for the member to share the impact of his or her style on others.
C19: L2P3 | D19: Introduction to Toastmasters Mentoring | E19: =E8 -> ■ The purpose of this project is for the member to clearly define how Toastmasters envisions mentoring. ■ The purpose of this speech is for the member to share some aspect of a previous experience as a protégé.
C20: L3P1 | D20: Reaching Consensus | E20: ■ The purpose of this project is for the member to work with a group to practice reaching consensus on any topic.
C21: L4P1 | D21: Improvement Through Positive Coaching | E21: ■ The purpose of this project is for the member to develop and apply skills for coaching a fellow member or a person outside of Toastmasters who can benefit from his or her expertise. ■ The purpose of this speech is for the member to share some aspect of his or her experience coaching.
C22: L5P1 | D22: High Performance Leadership | E22: ■ The purpose of this project is for the member to apply his or her leadership and planning knowledge to develop a project plan, organize a guidance committee, and implement the plan with the help of a team. ■ The purpose of the first speech is for the member to introduce his or her plan and vision.
C23: L5P2 | D23: Reflect on Your Path | E23: =E12 -> ■ The purpose of this project is for the member to reflect on his or her growth during the completion of an entire path. ■ The purpose of the speech is for the member to share some aspect of his or her growth during the completion of a path.
A24: Engaging Humor | B24: EH | C24: L1P1 | D24: Ice Breaker | E24: ■ The purpose of this project is for the member to introduce themselves to the club and learn the basic structure of a public speech.
C25: L1P2 | D25: Writing a Speech with Purpose | E25: ■ The purpose of this project is to learn or review basic methods for writing a speech with a defined purpose and to present a well-organized speech on any topic.
C26: L1P3 | D26: Introduction to Vocal Variety and Body Language | E26: ■ The purpose of this project is for the member to practice using vocal variety or body language to enhance a speech.
C27: L1P4 | D27: Evaluation and Feedback | E27: ■ The purpose of this project is to practice applying feedback and serve as a speech evaluator during a club meeting. ■ The purpose of this speech is for the member to present a speech and receive feedback from the evaluator.
C28: L2P1 | D28: Know Your Sense of Humor | E28: ■ The purpose of this project is to begin developing a collection of humorous stories and to present a speech that includes humor.
C29: L2P2 | D29: Connect with Your Audience | E29: ■ The purpose of this project is for the member to practice the skills needed to connect with an unfamiliar audience.
C30: L2P3 | D30: Introduction to Toastmasters Mentoring | E30: =E8 -> ■ The purpose of this project is for the member to clearly define how Toastmasters envisions mentoring. ■ The purpose of this speech is for the member to share some aspect of a previous experience as a protégé.
C31: L3P1 | D31: Engage Your Audience With Humor | E31: ■ The purpose of this project is for the member to determine their style of humor and apply it to a speech that centers around a central message.
C32: L4P1 | D32: The Power of Humor in an Impromptu Speech | E32: ■ The purpose of this project is for the member to develop their method for giving impromptu speeches and practice adapting rehearsed stories during a presentation.
C33: L5P1 | D33: Deliver Your Message With Humor | E33: ■ The purpose of this project is for the member to practice developing and presenting a longer humorous speech.
C34: L5P2 | D34: Reflect on Your Path | E34: =E12 -> ■ The purpose of this project is for the member to reflect on his or her growth during the completion of an entire path. ■ The purpose of the speech is for the member to share some aspect of his or her growth during the completion of a path.
A35: Innovative Planning | B35: IP | C35: L1P1 | D35: Ice Breaker | E35: ■ The purpose of this project is for the member to introduce themselves to the club and learn the basic structure of a public speech.
C36: L1P2 | D36: Writing a Speech with Purpose | E36: ■ The purpose of this project is to learn or review basic methods for writing a speech with a defined purpose and to present a well-organized speech on any topic.
C37: L1P3 | D37: Introduction to Vocal Variety and Body Language | E37: ■ The purpose of this project is for the member to practice using vocal variety or body language to enhance a speech.
C38: L1P4 | D38: Evaluation and Feedback | E38: ■ The purpose of this project is to practice applying feedback and serve as a speech evaluator during a club meeting. ■ The purpose of this speech is for the member to present a speech and receive feedback from the evaluator.
C39: L2P1 | D39: Understanding Your Leadership Style | E39: ■ The purpose of this project is for the member to identify his or her primary leadership style or styles. ■ The purpose of this speech is for the member to share some aspect of his or her primary leadership style or discuss leadership styles in general.
C40: L2P2 | D40: Connect With Your Audience | E40: ■ The purpose of this project is for the member to practice the skills needed to connect with an unfamiliar audience.
...

Sheet Pathways
A1: Name | B1: Pathway | C1: Path
A2: Yulin Lin | B2: VC2 | C2: VC | D2: Visionary Communication
A3: Pearl Huang | B3: LD4 | D3: Leadership Development | E3: L5P1
A4: Alex Huang | B4: DTM | C4: IP | D4: Dynamic Leadership | E4: L2P3
A5: Regina Cheng | B5: DTM
A6: Javier Bernabeu | B6: MS4 | C6: MS | D6: Motivational Strategies | E6: L4P1
A7: Eric Tang | B7: TC1 | C7: TC | D7: Team Collaboration
A8: Yaya Liao | B8: PM2 | C8: PM | D8: Presentation Mastery | E8: L2P3
A9: Dennis Chen | B9: IP3 | C9: IP | D9: Innovative Planning
A10: Tappy Hsieh | B10: PM2 | C10: PM | D10: Presentation Mastery | E10: L3P2
A11: Quentin Yao | C11: PM | D11: Presentation Mastery
A12: Anabela Liang | D12: Engaging Humor
A14: John Chiang | B14: LD1
A15: Hana Lin | B15: PM | C15: PM | D15: Presentation Mastery
A16: Bruce Fan | C16: EH | D16: Engaging Humor
A17: Eloise Hsu | B17: EH1 | C17: EH | D17: Engaging Humor
A18: Carol Chang | B18: PM3 | C18: L3 | D18: Presentation Mastery
A19: Marinda Kan | B19: PM1
